Workbook

Sheet README
A1: MIT PROJECT: AI CUSTOMER CHURN RESEARCH DATA WORKBOOK
A3: Purpose | B3: SPSS/Excel-ready coding, raw-data entry, response tracking, reliability planning, hypothesis mapping, and interview coding.
A4: Main sample target | B4: 420
A5: Pilot reliability sample | B5: 30
A6: Likert coding | B6: 1=Strongly Disagree; 2=Disagree; 3=Neutral; 4=Agree; 5=Strongly Agree
A7: H01 | B7: Pearson correlation: AIA_Mean vs PAC_Mean
A8: H02 | B8: Multiple regression: RSO_Mean predicted by AIA_Mean, PAC_Mean, MLU_Mean
A9: H03 | B9: One-way ANOVA: CRE_Mean across A8 AI-adoption maturity groups (0-4)
A10: Important | B10: H03 is perception-based unless audited churn-rate data are added. Do not claim causality from the survey alone.
A11: Missing-data default | B11: Compute a construct mean only if at least 80% of its items are answered. Confirm this rule before final analysis.
A12: Data integrity | B12: Keep an untouched raw export. Never replace missing empirical results with invented values.
A14: Recommended workflow: Pilot -> Reliability review -> Freeze instrument -> Main data collection -> Clean copy -> SPSS/Excel analysis -> Interviews -> Mixed-method integration -> Chapter Four

Sheet Codebook
A1: Variable | B1: Section | C1: Question / Label | D1: Response Type | E1: Coding / Values | F1: Construct | G1: Objective | H1: Research Question | I1: Hypothesis / Planned Analysis | J1: Include in Composite
A2: Consent | B2: A | C2: Consent to participate | D2: categorical | E2: Yes; No | F2: Eligibility/Consent | J2: No
A3: A1 | B3: A | C3: Gender (optional) | D3: categorical | E3: Male; Female; Prefer not to say; Other | F3: Demographic | J3: No
A4: A2 | B4: A | C4: Age group | D4: categorical | E4: 18-24; 25-34; 35-44; 45-54; 55 or above | F4: Demographic | J4: No
A5: A3 | B5: A | C5: Highest qualification | D5: categorical | E5: Diploma/OND/NCE; Bachelor/HND; Postgraduate Diploma; Master's; Doctorate; Other | F5: Demographic | J5: No
A6: A4 | B6: A | C6: Type of institution | D6: categorical | E6: Commercial bank; Digital bank/neobank; Merchant bank; Microfinance bank; Fintech/payment provider; Insurance/investment/other licensed financial institution | F6: Institutional profile | J6: No
A7: A5 | B7: A | C7: Current functional role | D7: categorical | E7: Digital Banking/Product; Data/Analytics/AI; IT/Technology; Customer Experience/Service; Relationship/Marketing; Risk/Compliance; Management/Strategy; Other | F7: Institutional profile | J7: No
A8: A6 | B8: A | C8: Years of professional experience | D8: categorical | E8: Less than 2; 2-5; 6-10; 11-15; 16 or more | F8: Institutional profile | J8: No
A9: A7 | B9: A | C9: Direct involvement with digital banking, AI, analytics, customer experience or retention | D9: categorical | E9: Yes; No | F9: Eligibility/Exposure | J9: No
A10: A8 | B10: A | C10: AI adoption maturity for customer analytics/retention | D10: ordinal | E10: 0=None; 1=Exploratory/pilot; 2=Limited deployment; 3=Established multi-use-case; 4=Advanced/enterprise-wide | F10: AI maturity | G10: 4 | H10: RQ4 | I10: H03 / One-way ANOVA | J10: No
A11: A9 | B11: A | C11: Institution currently uses predictive model/advanced analytics for churn risk | D11: categorical | E11: Yes; No; Do not know | F11: Institutional profile | G11: 2,4 | H11: RQ2,RQ4 | J11: No
A12: A10 | B12: A | C12: Primary work location / responding unit is within Eti-Osa LGA | D12: categorical | E12: Yes; No | F12: Eligibility | J12: No
A13: CHD1 | B13: B | C13: Frequent transaction failures increase the likelihood that customers reduce or stop using a bank. | D13: Likert 1-5 | E13: 1=SD; 2=D; 3=N; 4=A; 5=SA | F13: CHD | G13: 1 | H13: RQ1 | I13: Descriptive / Ranking | J13: Yes
A14: CHD2 | B14: B | C14: Unplanned downtime or unreliable digital channels contribute significantly to customer churn. | D14: Likert 1-5 | E14: 1=SD; 2=D; 3=N; 4=A; 5=SA | F14: CHD | G14: 1 | H14: RQ1 | I14: Descriptive / Ranking | J14: Yes
A15: CHD3 | B15: B | C15: Slow or ineffective resolution of complaints increases customers' likelihood of switching providers. | D15: Likert 1-5 | E15: 1=SD; 2=D; 3=N; 4=A; 5=SA | F15: CHD | G15: 1 | H15: RQ1 | I15: Descriptive / Ranking | J15: Yes
A16: CHD4 | B16: B | C16: High, unclear, or unexpected transaction charges contribute to customer churn. | D16: Likert 1-5 | E16: 1=SD; 2=D; 3=N; 4=A; 5=SA | F16: CHD | G16: 1 | H16: RQ1 | I16: Descriptive / Ranking | J16: Yes
A17: CHD5 | B17: B | C17: Fraud, cybersecurity incidents, or fear of financial loss reduce customers' willingness to remain with a provider. | D17: Likert 1-5 | E17: 1=SD; 2=D; 3=N; 4=A; 5=SA | F17: CHD | G17: 1 | H17: RQ1 | I17: Descriptive / Ranking | J17: Yes
A18: CHD6 | B18: B | C18: Poor usability or a difficult digital banking experience contributes to customer disengagement. | D18: Likert 1-5 | E18: 1=SD; 2=D; 3=N; 4=A; 5=SA | F18: CHD | G18: 1 | H18: RQ1 | I18: Descriptive / Ranking | J18: Yes
A19: CHD7 | B19: B | C19: Lack of relevant and personalized products or communication increases churn risk. | D19: Likert 1-5 | E19: 1=SD; 2=D; 3=N; 4=A; 5=SA | F19: CHD | G19: 1 | H19: RQ1 | I19: Descriptive / Ranking | J19: Yes
A20: CHD8 | B20: B | C20: More attractive services from fintechs, digital banks, or competing institutions increase customers' likelihood of switching. | D20: Likert 1-5 | E20: 1=SD; 2=D; 3=N; 4=A; 5=SA | F20: CHD | G20: 1 | H20: RQ1 | I20: Descriptive / Ranking | J20: Yes
A21: CHD9 | B21: B | C21: Declining trust in a financial institution is a major driver of customer churn. | D21: Likert 1-5 | E21: 1=SD; 2=D; 3=N; 4=A; 5=SA | F21: CHD | G21: 1 | H21: RQ1 | I21: Descriptive / Ranking | J21: Yes
A22: CHD10 | B22: B | C22: Repeated service problems can cause silent churn, where customers keep an account but move most activity elsewhere. | D22: Likert 1-5 | E22: 1=SD; 2=D; 3=N; 4=A; 5=SA | F22: CHD | G22: 1 | H22: RQ1 | I22: Descriptive / Ranking | J22: Yes
A23: AIA1 | B23: C | C23: My institution uses AI or advanced analytics to monitor changes in customer behaviour. | D23: Likert 1-5 | E23: 1=SD; 2=D; 3=N; 4=A; 5=SA | F23: AIA | G23: 2 | H23: RQ2 | I23: H01 Pearson; H02 Regression | J23: Yes
A24: AIA2 | B24: C | C24: Customer data from multiple digital touchpoints are integrated for churn or retention analysis. | D24: Likert 1-5 | E24: 1=SD; 2=D; 3=N; 4=A; 5=SA | F24: AIA | G24: 2 | H24: RQ2 | I24: H01 Pearson; H02 Regression | J24: Yes
... A69: IMP8 | B69: F3 | C69: Accurate churn prediction will have limited retention value if underlying service-quality problems are not corrected. | D69: Likert 1-5 | E69: 1=SD; 2=D; 3=N; 4=A; 5=SA | F69: IMP | G69: 6 | H69: RQ6 | I69: Framework synthesis | J69: Yes
A70: CHD_Mean | B70: Derived | C70: Customer Churn Determinants mean | D70: Continuous 1-5 | E70: Formula / SPSS compute | F70: Customer Churn Determinants | I70: Derived composite | J70: Derived
A71: AIA_Mean | B71: Derived | C71: AI Adoption mean | D71: Continuous 1-5 | E71: Formula / SPSS compute | F71: AI Adoption | I71: Derived composite | J71: Derived
A72: PAC_Mean | B72: Derived | C72: Predictive Analytics Capability mean | D72: Continuous 1-5 | E72: Formula / SPSS compute | F72: Predictive Analytics Capability | I72: Derived composite | J72: Derived
A73: MLU_Mean | B73: Derived | C73: ML Technique Suitability mean | D73: Continuous 1-5 | E73: Formula / SPSS compute | F73: ML Technique Suitability | I73: Derived composite | J73: Derived
A74: RSO_Mean | B74: Derived | C74: Retention Strategy Optimization mean | D74: Continuous 1-5 | E74: Formula / SPSS compute | F74: Retention Strategy Optimization | I74: Derived composite | J74: Derived
A75: CRE_Mean | B75: Derived | C75: Customer Retention Effectiveness mean | D75: Continuous 1-5 | E75: Formula / SPSS compute | F75: Customer Retention Effectiveness | I75: Derived composite | J75: Derived
A76: IMP_Mean | B76: Derived | C76: Implementation/Governance mean | D76: Continuous 1-5 | E76: Formula / SPSS compute | F76: Implementation/Governance | I76: Derived composite | J76: Derived

Sheet Raw_Data
A1: Respondent_ID | B1: Valid_Record | C1: Consent | D1: A1 | E1: A2 | F1: A3 | G1: A4 | H1: A5 | I1: A6 | J1: A7 | K1: A8 | L1: A9 | M1: A10 | N1: CHD1 | O1: CHD2 | P1: CHD3 | Q1: CHD4 | R1: CHD5 | S1: CHD6 | T1: CHD7 | U1: CHD8 | V1: CHD9 | W1: CHD10 | X1: AIA1 | Y1: AIA2 | Z1: AIA3 | AA1: AIA4 | AB1: AIA5 | AC1: AIA6 | AD1: AIA7 | AE1: AIA8 | AF1: PAC1 | AG1: PAC2 | AH1: PAC3 | AI1: PAC4 | AJ1: PAC5 | AK1: PAC6 | AL1: PAC7 | AM1: PAC8 | AN1: MLU1 | AO1: MLU2 | AP1: MLU3 | AQ1: MLU4 | AR1: MLU5 | AS1: MLU6 | AT1: MLU7 | AU1: MLU8 | AV1: MLU9 | AW1: RSO1 | AX1: RSO2 | AY1: RSO3 | AZ1: RSO4 | BA1: RSO5 | BB1: RSO6 | BC1: RSO7 | BD1: RSO8 | BE1: CRE1 | BF1: CRE2 | BG1: CRE3 | BH1: CRE4 | BI1: CRE5 | BJ1: CRE6 | BK1: IMP1 | BL1: IMP2 | BM1: IMP3 | BN1: IMP4 | BO1: IMP5 | BP1: IMP6 | BQ1: IMP7 | BR1: IMP8 | BS1: CHD_Mean | BT1: AIA_Mean | BU1: PAC_Mean | BV1: MLU_Mean | BW1: RSO_Mean | BX1: CRE_Mean | BY1: IMP_Mean
A2: P001 | B2: No | C2: Yes | D2: Male | E2: 25-34 | F2: Postgraduate Diploma | G2: Commercial bank | H2: Customer Experience/Service | I2: 6-10 | J2: Yes | K2: 2 | L2: Yes | M2: No | N2: 3 | O2: 3 | P2: 4 | Q2: 3 | R2: 3 | S2: 4 | T2: 3 | U2: 4 | V2: 4 | W2: 3 | X2: 4 | Y2: 3 | Z2: 5 | AA2: 2 | AB2: 5 | AC2: 3 | AD2: 4 | AE2: 3 | AF2: 3 | AG2: 4 | AH2: 3 | AI2: 4 | AJ2: 2 | AK2: 2 | AL2: 3 | AM2: 4 | AN2: 3 | AO2: 3 | AP2: 2 | AQ2: 3 | AR2: 2 | AS2: 3 | AT2: 3 | AU2: 3 | AV2: 3 | AW2: 5 | AX2: 4 | AY2: 5 | AZ2: 4 | BA2: 5 | BB2: 4 | BC2: 4 | BD2: 4 | BE2: 4 | BG2: 3 | BH2: 3 | BI2: 2 | BJ2: 3 | BK2: 3 | BL2: 3 | BM2: 3 | BN2: 3 | BO2: 3 | BP2: 4 | BQ2: 2 | BR2: 2 | BS2: =IF(COUNT(N2:W2)>=8,AVERAGE(N2:W2),"") | BT2: =IF(COUNT(X2:AE2)>=7,AVERAGE(X2:AE2),"") | BU2: =IF(COUNT(AF2:AM2)>=7,AVERAGE(AF2:AM2),"") | BV2: =IF(COUNT(AN2:AV2)>=8,AVERAGE(AN2:AV2),"") | BW2: =IF(COUNT(AW2:BD2)>=7,AVERAGE(AW2:BD2),"") | BX2: =IF(COUNT(BE2:BJ2)>=5,AVERAGE(BE2:BJ2),"") | BY2: =IF(COUNT(BK2:BR2)>=7,AVERAGE(BK2:BR2),"")
A3: P002 | B3: No | C3: Yes | D3: Female | E3: 18-24 | F3: Bachelor/HND | G3: Insurance/investment/other licensed financial institution | H3: Digital Banking/Product | I3: 2-5 | J3: Yes | K3: 1 | L3: No | M3: No | N3: 4 | O3: 2 | P3: 4 | Q3: 3 | R3: 4 | S3: 4 | T3: 3 | U3: 3 | V3: 4 | W3: 4 | X3: 3 | Y3: 2 | Z3: 4 | AA3: 3 | AB3: 3 | AC3: 4 | AD3: 4 | AE3: 3 | AF3: 3 | AG3: 4 | AH3: 3 | AI3: 4 | AJ3: 3 | AL3: 4 | AM3: 3 | AN3: 4 | AO3: 3 | AP3: 4 | AQ3: 2 | AR3: 3 | AS3: 2 | AT3: 3 | AU3: 3 | AV3: 3 | AW3: 3 | AX3: 3 | AY3: 4 | AZ3: 4 | BA3: 3 | BB3: 3 | BC3: 4 | BD3: 3 | BE3: 5 | BF3: 4 | BG3: 4 | BH3: 3 | BI3: 4 | BJ3: 3 | BK3: 4 | BL3: 4 | BM3: 3 | BN3: 3 | BO3: 4 | BP3: 3 | BQ3: 4 | BR3: 3 | BS3: =IF(COUNT(N3:W3)>=8,AVERAGE(N3:W3),"") | BT3: =IF(COUNT(X3:AE3)>=7,AVERAGE(X3:AE3),"") | BU3: =IF(COUNT(AF3:AM3)>=7,AVERAGE(AF3:AM3),"") | BV3: =IF(COUNT(AN3:AV3)>=8,AVERAGE(AN3:AV3),"") | BW3: =IF(COUNT(AW3:BD3)>=7,AVERAGE(AW3:BD3),"") | BX3: =IF(COUNT(BE3:BJ3)>=5,AVERAGE(BE3:BJ3),"") | BY3: =IF(COUNT(BK3:BR3)>=7,AVERAGE(BK3:BR3),"")
A4: P003 | B4: No | C4: Yes | D4: Female | E4: 55 or above | F4: Postgraduate Diploma | G4: Commercial bank | H4: Customer Experience/Service | I4: 2-5 | J4: Yes | K4: 0 | L4: No | M4: No | N4: 4 | O4: 4 | P4: 3 | Q4: 3 | R4: 3 | S4: 4 | T4: 2 | U4: 4 | V4: 5 | W4: 4 | X4: 3 | Y4: 2 | Z4: 2 | AA4: 3 | AB4: 4 | AC4: 4 | AD4: 4 | AE4: 3 | AF4: 3 | AG4: 4 | AH4: 3 | AI4: 3 | AJ4: 4 | AK4: 3 | AL4: 4 | AM4: 3 | AO4: 2 | AP4: 3 | AQ4: 4 | AR4: 4 | AS4: 3 | AT4: 3 | AU4: 3 | AV4: 4 | AW4: 4 | AX4: 3 | AY4: 3 | AZ4: 2 | BA4: 4 | BB4: 4 | BC4: 3 | BD4: 3 | BE4: 1 | BF4: 3 | BG4: 1 | BH4: 2 | BI4: 3 | BJ4: 2 | BK4: 3 | BL4: 3 | BM4: 2 | BN4: 4 | BO4: 2 | BP4: 3 | BQ4: 3 | BR4: 2 | BS4: =IF(COUNT(N4:W4)>=8,AVERAGE(N4:W4),"") | BT4: =IF(COUNT(X4:AE4)>=7,AVERAGE(X4:AE4),"") | BU4: =IF(COUNT(AF4:AM4)>=7,AVERAGE(AF4:AM4),"") | BV4: =IF(COUNT(AN4:AV4)>=8,AVERAGE(AN4:AV4),"") | BW4: =IF(COUNT(AW4:BD4)>=7,AVERAGE(AW4:BD4),"") | BX4: =IF(COUNT(BE4:BJ4)>=5,AVERAGE(BE4:BJ4),"") | BY4: =IF(COUNT(BK4:BR4)>=7,AVERAGE(BK4:BR4),"")
A5: P004 | B5: No | C5: Yes | D5: Female | E5: 45-54 | F5: Bachelor/HND | G5: Microfinance bank | H5: Management/Strategy | I5: 2-5 | J5: Yes | K5: 2 | L5: Yes | M5: No | N5: 4 | O5: 3 | P5: 5 | Q5: 4 | R5: 4 | S5: 5 | U5: 3 | V5: 4 | W5: 3 | X5: 3 | Y5: 4 | AA5: 4 | AB5: 3 | AC5: 4 | AD5: 4 | AE5: 3 | AF5: 3 | AG5: 5 | AH5: 3 | AI5: 3 | AJ5: 3 | AK5: 4 | AL5: 4 | AN5: 4 | AO5: 3 | AP5: 4 | AQ5: 3 | AR5: 5 | AS5: 4 | AT5: 4 | AU5: 4 | AV5: 4 | AW5: 4 | AX5: 3 | AY5: 4 | AZ5: 3 | BA5: 4 | BB5: 4 | BC5: 4 | BD5: 4 | BE5: 3 | BF5: 4 | BH5: 4 | BI5: 4 | BJ5: 3 | BK5: 3 | BL5: 2 | BM5: 2 | BN5: 3 | BO5: 3 | BP5: 2 | BQ5: 4 | BR5: 3 | BS5: =IF(COUNT(N5:W5)>=8,AVERAGE(N5:W5),"") | BT5: =IF(COUNT(X5:AE5)>=7,AVERAGE(X5:AE5),"") | BU5: =IF(COUNT(AF5:AM5)>=7,AVERAGE(AF5:AM5),"") | BV5: =IF(COUNT(AN5:AV5)>=8,AVERAGE(AN5:AV5),"") | BW5: =IF(COUNT(AW5:BD5)>=7,AVERAGE(AW5:BD5),"") | BX5: =IF(COUNT(BE5:BJ5)>=5,AVERAGE(BE5:BJ5),"") | BY5: =IF(COUNT(BK5:BR5)>=7,AVERAGE(BK5:BR5),"")
A6: P005 | B6: No | C6: Yes | D6: Male | E6: 55 or above | F6: Master's | G6: Commercial bank | H6: Risk/Compliance | I6: 2-5 | J6: Yes | K6: 0 | L6: No | M6: No | N6: 3 | O6: 2 | P6: 3 | Q6: 3 | R6: 3 | S6: 2 | T6: 2 | U6: 2 | V6: 2 | W6: 3 | X6: 3 | Y6: 3 | Z6: 3 | AA6: 2 | AB6: 2 | AC6: 3 | AD6: 3 | AE6: 3 | AF6: 4 | AG6: 2 | AH6: 2 | AI6: 3 | AJ6: 2 | AK6: 3 | AL6: 2 | AM6: 3 | AN6: 1 | AO6: 2 | AP6: 1 | AQ6: 1 | AR6: 1 | AS6: 1 | AT6: 1 | AU6: 3 | AV6: 2 | AW6: 3 | AX6: 1 | AY6: 2 | AZ6: 2 | BA6: 2 | BB6: 1 | BC6: 3 | BD6: 2 | BE6: 2 | BF6: 4 | BG6: 3 | BH6: 4 | BI6: 4 | BJ6: 3 | BK6: 3 | BL6: 3 | BM6: 4 | BN6: 3 | BO6: 3 | BP6: 2 | BQ6: 4 | BR6: 2 | BS6: =IF(COUNT(N6:W6)>=8,AVERAGE(N6:W6),"") | BT6: =IF(COUNT(X6:AE6)>=7,AVERAGE(X6:AE6),"") | BU6: =IF(COUNT(AF6:AM6)>=7,AVERAGE(AF6:AM6),"") | BV6: =IF(COUNT(AN6:AV6)>=8,AVERAGE(AN6:AV6),"") | BW6: =IF(COUNT(AW6:BD6)>=7,AVERAGE(AW6:BD6),"") | BX6: =IF(COUNT(BE6:BJ6)>=5,AVERAGE(BE6:BJ6),"") | BY6: =IF(COUNT(BK6:BR6)>=7,AVERAGE(BK6:BR6),"")
A7: P006 | B7: No | C7: Yes | D7: Female | E7: 35-44 | F7: Bachelor/HND | G7: Commercial bank | H7: Digital Banking/Product | I7: Less than 2 | J7: Yes | K7: 4 | L7: Yes | M7: No | N7: 2 | O7: 2 | P7: 2 | Q7: 2 | R7: 3 | S7: 3 | T7: 2 | U7: 4 | V7: 3 | W7: 2 | Y7: 3 | Z7: 5 | AA7: 3 | AB7: 4 | AC7: 4 | AD7: 3 | AE7: 3 | AF7: 4 | AG7: 2 | AH7: 3 | AI7: 4 | AJ7: 2 | AK7: 5 | AL7: 4 | AM7: 3 | AN7: 4 | AO7: 4 | AP7: 4 | AQ7: 5 | AR7: 3 | AS7: 3 | AT7: 4 | AU7: 3 | AV7: 4 | AW7: 2 | AX7: 3 | AY7: 3 | AZ7: 2 | BA7: 3 | BB7: 3 | BC7: 4 | BD7: 3 | BF7: 3 | BG7: 3 | BH7: 3 | BI7: 3 | BJ7: 3 | BK7: 3 | BL7: 2 | BM7: 4 | BN7: 3 | BO7: 3 | BP7: 2 | BQ7: 3 | BS7: =IF(COUNT(N7:W7)>=8,AVERAGE(N7:W7),"") | BT7: =IF(COUNT(X7:AE7)>=7,AVERAGE(X7:AE7),"") | BU7: =IF(COUNT(AF7:AM7)>=7,AVERAGE(AF7:AM7),"") | BV7: =IF(COUNT(AN7:AV7)>=8,AVERAGE(AN7:AV7),"") | BW7: =IF(COUNT(AW7:BD7)>=7,AVERAGE(AW7:BD7),"") | BX7: =IF(COUNT(BE7:BJ7)>=5,AVERAGE(BE7:BJ7),"") | BY7: =IF(COUNT(BK7:BR7)>=7,AVERAGE(BK7:BR7),"")
A8: P007 | B8: No | C8: Yes | D8: Male | E8: 25-34 | F8: Diploma/OND/NCE | G8: Digital bank/neobank | H8: IT/Technology | I8: 16 or more | J8: Yes | K8: 2 | L8: Yes | M8: No | N8: 3 | O8: 3 | P8: 3 | Q8: 2 | R8: 3 | S8: 3 | T8: 2 | U8: 3 | V8: 3 | W8: 2 | X8: 3 | Y8: 2 | Z8: 3 | AA8: 3 | AB8: 2 | AC8: 2 | AD8: 3 | AE8: 1 | AF8: 2 | AG8: 2 | AH8: 3 | AI8: 3 | AJ8: 3 | AK8: 3 | AL8: 3 | AM8: 4 | AN8: 3 | AP8: 2 | AQ8: 2 | AR8: 4 | AS8: 4 | AT8: 3 | AU8: 3 | AV8: 4 | AW8: 2 | AX8: 2 | AY8: 2 | AZ8: 2 | BA8: 4 | BB8: 3 | BC8: 3 | BD8: 3 | BE8: 4 | BF8: 5 | BG8: 3 | BH8: 4 | BI8: 3 | BJ8: 3 | BK8: 3 | BL8: 2 | BM8: 3 | BN8: 3 | BO8: 4 | BP8: 4 | BQ8: 4 | BR8: 3 | BS8: =IF(COUNT(N8:W8)>=8,AVERAGE(N8:W8),"") | BT8: =IF(COUNT(X8:AE8)>=7,AVERAGE(X8:AE8),"") | BU8: =IF(COUNT(AF8:AM8)>=7,AVERAGE(AF8:AM8),"") | BV8: =IF(COUNT(AN8:AV8)>=8,AVERAGE(AN8:AV8),"") | BW8: =IF(COUNT(AW8:BD8)>=7,AVERAGE(AW8:BD8),"") | BX8: =IF(COUNT(BE8:BJ8)>=5,AVERAGE(BE8:BJ8),"") | BY8: =IF(COUNT(BK8:BR8)>=7,AVERAGE(BK8:BR8),"")
A9: P008 | B9: No | C9: Yes | D9: Male | E9: 18-24 | F9: Bachelor/HND | G9: Commercial bank | H9: Relationship/Marketing | I9: Less than 2 | J9: Yes | K9: 2 | L9: Yes | M9: No | N9: 3 | O9: 2 | P9: 3 | Q9: 2 | R9: 1 | S9: 2 | T9: 2 | U9: 2 | V9: 4 | W9: 2 | X9: 3 | Y9: 1 | Z9: 1 | AA9: 1 | AB9: 1 | AC9: 1 | AD9: 2 | AE9: 1 | AF9: 2 | AG9: 2 | AH9: 2 | AI9: 1 | AJ9: 2 | AK9: 2 | AL9: 3 | AM9: 2 | AN9: 3 | AO9: 3 | AP9: 3 | AQ9: 2 | AR9: 3 | AS9: 3 | AT9: 3 | AU9: 2 | AV9: 2 | AW9: 3 | AX9: 1 | AY9: 1 | AZ9: 1 | BA9: 1 | BB9: 1 | BC9: 2 | BD9: 1 | BE9: 3 | BF9: 5 | BG9: 3 | BH9: 4 | BI9: 4 | BJ9: 3 | BK9: 3 | BL9: 3 | BM9: 4 | BN9: 3 | BO9: 4 | BQ9: 4 | BR9: 3 | BS9: =IF(COUNT(N9:W9)>=8,AVERAGE(N9:W9),"") | BT9: =IF(COUNT(X9:AE9)>=7,AVERAGE(X9:AE9),"") | BU9: =IF(COUNT(AF9:AM9)>=7,AVERAGE(AF9:AM9),"") | BV9: =IF(COUNT(AN9:AV9)>=8,AVERAGE(AN9:AV9),"") | BW9: =IF(COUNT(AW9:BD9)>=7,AVERAGE(AW9:BD9),"") | BX9: =IF(COUNT(BE9:BJ9)>=5,AVERAGE(BE9:BJ9),"") | BY9: =IF(COUNT(BK9:BR9)>=7,AVERAGE(BK9:BR9),"")
A10: P009 | B10: No | C10: Yes | D10: Male | E10: 25-34 | F10: Bachelor/HND | G10: Microfinance bank | H10: IT/Technology | I10: Less than 2 | J10: Yes | K10: 1 | L10: No | M10: No | N10: 4 | O10: 3 | P10: 5 | Q10: 4 | R10: 4 | S10: 5 | T10: 4 | U10: 4 | V10: 4 | W10: 4 | X10: 1 | Y10: 2 | Z10: 3 | AA10: 3 | AB10: 2 | AC10: 3 | AD10: 3 | AE10: 3 | AF10: 2 | AG10: 3 | AH10: 2 | AI10: 4 | AJ10: 2 | AK10: 3 | AL10: 3 | AM10: 2 | AN10: 4 | AO10: 4 | AP10: 3 | AQ10: 3 | AR10: 4 | AS10: 4 | AT10: 3 | AU10: 4 | AV10: 3 | AW10: 3 | AX10: 2 | AZ10: 1 | BA10: 2 | BB10: 2 | BC10: 2 | BD10: 2 | BE10: 4 | BF10: 3 | BG10: 2 | BH10: 3 | BI10: 2 | BJ10: 3 | BK10: 4 | BL10: 3 | BM10: 5 | BN10: 3 | BO10: 3 | BP10: 3 | BQ10: 4 | BR10: 3 | BS10: =IF(COUNT(N10:W10)>=8,AVERAGE(N10:W10),"") | BT10: =IF(COUNT(X10:AE10)>=7,AVERAGE(X10:AE10),"") | BU10: =IF(COUNT(AF10:AM10)>=7,AVERAGE(AF10:AM10),"") | BV10: =IF(COUNT(AN10:AV10)>=8,AVERAGE(AN10:AV10),"") | BW10: =IF(COUNT(AW10:BD10)>=7,AVERAGE(AW10:BD10),"") | BX10: =IF(COUNT(BE10:BJ10)>=5,AVERAGE(BE10:BJ10),"") | BY10: =IF(COUNT(BK10:BR10)>=7,AVERAGE(BK10:BR10),"")
A11: P010 | B11: No | C11: Yes | D11: Female | E11: 25-34 | F11: Bachelor/HND | G11: Merchant bank | H11: IT/Technology | I11: Less than 2 | J11: Yes | K11: 0 | L11: Yes | M11: No | N11: 4 | O11: 2 | P11: 4 | Q11: 3 | R11: 4 | S11: 3 | T11: 3 | U11: 3 | V11: 3 | W11: 3 | X11: 2 | Y11: 2 | Z11: 2 | AA11: 2 | AB11: 1 | AC11: 2 | AD11: 3 | AE11: 2 | AF11: 4 | AG11: 3 | AH11: 5 | AI11: 3 | AJ11: 3 | AK11: 3 | AL11: 4 | AM11: 4 | AN11: 4 | AP11: 4 | AQ11: 3 | AR11: 3 | AS11: 3 | AT11: 3 | AU11: 3 | AV11: 3 | AW11: 4 | AX11: 4 | AY11: 2 | AZ11: 3 | BA11: 4 | BB11: 3 | BC11: 4 | BD11: 3 | BE11: 3 | BF11: 2 | BG11: 1 | BH11: 3 | BI11: 3 | BJ11: 2 | BK11: 2 | BL11: 2 | BM11: 4 | BN11: 3 | BO11: 3 | BP11: 2 | BQ11: 3 | BR11: 2 | BS11: =IF(COUNT(N11:W11)>=8,AVERAGE(N11:W11),"") | BT11: =IF(COUNT(X11:AE11)>=7,AVERAGE(X11:AE11),"") | BU11: =IF(COUNT(AF11:AM11)>=7,AVERAGE(AF11:AM11),"") | BV11: =IF(COUNT(AN11:AV11)>=8,AVERAGE(AN11:AV11),"") | BW11: =IF(COUNT(AW11:BD11)>=7,AVERAGE(AW11:BD11),"") | BX11: =IF(COUNT(BE11:BJ11)>=5,AVERAGE(BE11:BJ11),"") | BY11: =IF(COUNT(BK11:BR11)>=7,AVERAGE(BK11:BR11),"")
A12: P011 | B12: No | C12: Yes | D12: Female | E12: 25-34 | F12: Doctorate | G12: Commercial bank | H12: Other | I12: Less than 2 | J12: Yes | K12: 1 | L12: No | M12: No | N12: 2 | O12: 3 | P12: 2 | Q12: 2 | R12: 3 | S12: 4 | T12: 1 | U12: 2 | V12: 3 | W12: 1 | X12: 3 | Y12: 2 | Z12: 2 | AA12: 2 | AC12: 2 | AD12: 4 | AE12: 1 | AF12: 1 | AG12: 1 | AH12: 2 | AI12: 3 | AJ12: 1 | AK12: 2 | AL12: 1 | AM12: 1 | AN12: 3 | AO12: 2 | AP12: 2 | AQ12: 2 | AR12: 3 | AS12: 3 | AT12: 3 | AU12: 1 | AV12: 2 | AW12: 2 | AX12: 3 | AY12: 2 | AZ12: 2 | BA12: 2 | BB12: 2 | BC12: 3 | BD12: 2 | BE12: 3 | BG12: 2 | BH12: 4 | BI12: 3 | BJ12: 3 | BK12: 3 | BL12: 3 | BM12: 4 | BN12: 4 | BO12: 4 | BP12: 3 | BQ12: 4 | BR12: 3 | BS12: =IF(COUNT(N12:W12)>=8,AVERAGE(N12:W12),"") | BT12: =IF(COUNT(X12:AE12)>=7,AVERAGE(X12:AE12),"") | BU12: =IF(COUNT(AF12:AM12)>=7,AVERAGE(AF12:AM12),"") | BV12: =IF(COUNT(AN12:AV12)>=8,AVERAGE(AN12:AV12),"") | BW12: =IF(COUNT(AW12:BD12)>=7,AVERAGE(AW12:BD12),"") | BX12: =IF(COUNT(BE12:BJ12)>=5,AVERAGE(BE12:BJ12),"") | BY12: =IF(COUNT(BK12:BR12)>=7,AVERAGE(BK12:BR12),"")
A13: P012 | B13: No | C13: Yes | D13: Male | E13: 25-34 | F13: Diploma/OND/NCE | G13: Commercial bank | H13: Digital Banking/Product | I13: 2-5 | J13: Yes | K13: 2 | L13: Yes | M13: No | N13: 3 | O13: 3 | P13: 3 | Q13: 2 | R13: 2 | S13: 3 | T13: 2 | U13: 2 | V13: 3 | W13: 2 | X13: 3 | Y13: 3 | Z13: 5 | AA13: 4 | AB13: 4 | AC13: 4 | AD13: 4 | AE13: 5 | AF13: 3 | AG13: 4 | AH13: 3 | AI13: 5 | AJ13: 4 | AK13: 3 | AL13: 3 | AM13: 3 | AN13: 4 | AO13: 4 | AP13: 3 | AQ13: 3 | AR13: 4 | AS13: 4 | AT13: 3 | AU13: 3 | AW13: 4 | AX13: 3 | AY13: 2 | AZ13: 4 | BA13: 5 | BB13: 4 | BC13: 4 | BD13: 3 | BE13: 2 | BF13: 4 | BG13: 4 | BH13: 4 | BI13: 4 | BJ13: 4 | BK13: 3 | BL13: 3 | BM13: 5 | BN13: 3 | BO13: 5 | BP13: 2 | BQ13: 3 | BR13: 4 | BS13: =IF(COUNT(N13:W13)>=8,AVERAGE(N13:W13),"") | BT13: =IF(COUNT(X13:AE13)>=7,AVERAGE(X13:AE13),"") | BU13: =IF(COUNT(AF13:AM13)>=7,AVERAGE(AF13:AM13),"") | BV13: =IF(COUNT(AN13:AV13)>=8,AVERAGE(AN13:AV13),"") | BW13: =IF(COUNT(AW13:BD13)>=7,AVERAGE(AW13:BD13),"") | BX13: =IF(COUNT(BE13:BJ13)>=5,AVERAGE(BE13:BJ13),"") | BY13: =IF(COUNT(BK13:BR13)>=7,AVERAGE(BK13:BR13),"")
A14: P013 | B14: No | C14: Yes | D14: Female | E14: 25-34 | F14: Bachelor/HND | G14: Commercial bank | H14: Data/Analytics/AI | I14: 2-5 | J14: Yes | K14: 3 | L14: No | M14: No | N14: 2 | O14: 1 | P14: 2 | Q14: 1 | R14: 1 | S14: 1 | T14: 1 | U14: 1 | V14: 3 | W14: 2 | X14: 2 | Y14: 4 | Z14: 5 | AA14: 3 | AB14: 4 | AC14: 4 | AD14: 4 | AE14: 2 | AF14: 3 | AG14: 4 | AH14: 3 | AI14: 4 | AJ14: 3 | AK14: 3 | AL14: 3 | AM14: 4 | AN14: 3 | AO14: 2 | AP14: 2 | AQ14: 1 | AR14: 3 | AS14: 3 | AT14: 2 | AU14: 2 | AV14: 3 | AW14: 4 | AX14: 3 | AY14: 3 | AZ14: 3 | BA14: 3 | BB14: 4 | BC14: 3 | BD14: 2 | BE14: 4 | BF14: 3 | BG14: 4 | BH14: 4 | BI14: 4 | BJ14: 4 | BK14: 3 | BL14: 2 | BM14: 3 | BN14: 3 | BO14: 2 | BP14: 2 | BQ14: 3 | BR14: 3 | BS14: =IF(COUNT(N14:W14)>=8,AVERAGE(N14:W14),"") | BT14: =IF(COUNT(X14:AE14)>=7,AVERAGE(X14:AE14),"") | BU14: =IF(COUNT(AF14:AM14)>=7,AVERAGE(AF14:AM14),"") | BV14: =IF(COUNT(AN14:AV14)>=8,AVERAGE(AN14:AV14),"") | BW14: =IF(COUNT(AW14:BD14)>=7,AVERAGE(AW14:BD14),"") | BX14: =IF(COUNT(BE14:BJ14)>=5,AVERAGE(BE14:BJ14),"") | BY14: =IF(COUNT(BK14:BR14)>=7,AVERAGE(BK14:BR14),"")
A15: P014 | B15: No | C15: Yes | D15: Female | E15: 45-54 | F15: Postgraduate Diploma | G15: Commercial bank | H15: IT/Technology | I15: 2-5 | J15: Yes | K15: 4 | L15: Do not know | M15: No | N15: 3 | O15: 4 | P15: 3 | Q15: 3 | R15: 2 | S15: 3 | T15: 2 | U15: 3 | V15: 2 | W15: 2 | X15: 3 | Y15: 4 | Z15: 3 | AA15: 3 | AB15: 3 | AC15: 3 | AD15: 4 | AE15: 4 | AF15: 3 | AG15: 4 | AH15: 3 | AI15: 4 | AJ15: 4 | AK15: 3 | AL15: 4 | AM15: 4 | AN15: 3 | AO15: 4 | AP15: 5 | AQ15: 2 | AR15: 3 | AS15: 2 | AT15: 4 | AU15: 2 | AV15: 3 | AW15: 4 | AX15: 3 | AY15: 3 | AZ15: 2 | BB15: 3 | BC15: 4 | BD15: 4 | BE15: 3 | BF15: 4 | BG15: 3 | BH15: 4 | BI15: 4 | BJ15: 3 | BK15: 4 | BL15: 4 | BM15: 3 | BN15: 2 | BO15: 3 | BQ15: 3 | BR15: 2 | BS15: =IF(COUNT(N15:W15)>=8,AVERAGE(N15:W15),"") | BT15: =IF(COUNT(X15:AE15)>=7,AVERAGE(X15:AE15),"") | BU15: =IF(COUNT(AF15:AM15)>=7,AVERAGE(AF15:AM15),"") | BV15: =IF(COUNT(AN15:AV15)>=8,AVERAGE(AN15:AV15),"") | BW15: =IF(COUNT(AW15:BD15)>=7,AVERAGE(AW15:BD15),"") | BX15: =IF(COUNT(BE15:BJ15)>=5,AVERAGE(BE15:BJ15),"") | BY15: =IF(COUNT(BK15:BR15)>=7,AVERAGE(BK15:BR15),"")
A16: P015 | B16: No | C16: Yes | D16: Male | E16: 35-44 | F16: Other | G16: Digital bank/neobank | H16: Relationship/Marketing | I16: 6-10 | J16: Yes | K16: 1 | L16: No | M16: No | N16: 5 | O16: 4 | P16: 4 | Q16: 4 | R16: 4 | S16: 5 | T16: 3 | U16: 4 | V16: 4 | W16: 4 | X16: 5 | Y16: 4 | Z16: 5 | AA16: 3 | AB16: 4 | AC16: 4 | AD16: 4 | AE16: 3 | AG16: 4 | AH16: 3 | AI16: 5 | AJ16: 3 | AK16: 5 | AL16: 4 | AM16: 3 | AN16: 3 | AO16: 3 | AP16: 2 | AQ16: 2 | AR16: 3 | AS16: 4 | AT16: 4 | AU16: 3 | AV16: 3 | AW16: 4 | AX16: 4 | AY16: 4 | AZ16: 3 | BA16: 5 | BB16: 3 | BC16: 3 | BD16: 4 | BE16: 2 | BF16: 1 | BG16: 1 | BH16: 3 | BI16: 2 | BJ16: 2 | BK16: 3 | BL16: 3 | BM16: 2 | BN16: 1 | BO16: 3 | BP16: 3 | BQ16: 3 | BR16: 3 | BS16: =IF(COUNT(N16:W16)>=8,AVERAGE(N16:W16),"") | BT16: =IF(COUNT(X16:AE16)>=7,AVERAGE(X16:AE16),"") | BU16: =IF(COUNT(AF16:AM16)>=7,AVERAGE(AF16:AM16),"") | BV16: =IF(COUNT(AN16:AV16)>=8,AVERAGE(AN16:AV16),"") | BW16: =IF(COUNT(AW16:BD16)>=7,AVERAGE(AW16:BD16),"") | BX16: =IF(COUNT(BE16:BJ16)>=5,AVERAGE(BE16:BJ16),"") | BY16: =IF(COUNT(BK16:BR16)>=7,AVERAGE(BK16:BR16),"")
A17: P016 | B17: No | C17: Yes | D17: Prefer not to say | E17: 25-34 | F17: Master's | G17: Digital bank/neobank | H17: Digital Banking/Product | I17: Less than 2 | J17: Yes | K17: 0 | L17: Yes | M17: No | N17: 3 | O17: 4 | P17: 4 | Q17: 2 | R17: 4 | S17: 2 | T17: 3 | U17: 4 | V17: 3 | W17: 3 | X17: 2 | Y17: 1 | Z17: 3 | AA17: 2 | AB17: 1 | AC17: 1 | AD17: 1 | AE17: 1 | AF17: 2 | AG17: 3 | AH17: 2 | AI17: 4 | AJ17: 2 | AK17: 3 | AL17: 3 | AM17: 1 | AN17: 2 | AO17: 2 | AP17: 2 | AQ17: 1 | AR17: 1 | AS17: 1 | AT17: 1 | AU17: 2 | AV17: 2 | AW17: 2 | AX17: 2 | AY17: 2 | AZ17: 1 | BA17: 2 | BB17: 1 | BC17: 1 | BD17: 1 | BE17: 3 | BF17: 3 | BG17: 2 | BH17: 2 | BI17: 2 | BJ17: 2 | BK17: 3 | BL17: 3 | BM17: 3 | BN17: 3 | BO17: 3 | BP17: 3 | BQ17: 4 | BR17: 3 | BS17: =IF(COUNT(N17:W17)>=8,AVERAGE(N17:W17),"") | BT17: =IF(COUNT(X17:AE17)>=7,AVERAGE(X17:AE17),"") | BU17: =IF(COUNT(AF17:AM17)>=7,AVERAGE(AF17:AM17),"") | BV17: =IF(COUNT(AN17:AV17)>=8,AVERAGE(AN17:AV17),"") | BW17: =IF(COUNT(AW17:BD17)>=7,AVERAGE(AW17:BD17),"") | BX17: =IF(COUNT(BE17:BJ17)>=5,AVERAGE(BE17:BJ17),"") | BY17: =IF(COUNT(BK17:BR17)>=7,AVERAGE(BK17:BR17),"")
A18: P017 | B18: No | C18: Yes | D18: Female | E18: 35-44 | F18: Master's | G18: Digital bank/neobank | H18: IT/Technology | I18: 11-15 | J18: Yes | K18: 4 | L18: Yes | M18: No | N18: 3 | O18: 3 | P18: 4 | Q18: 3 | R18: 3 | S18: 3 | T18: 2 | U18: 3 | V18: 3 | W18: 3 | X18: 3 | Y18: 3 | Z18: 2 | AA18: 3 | AB18: 2 | AC18: 3 | AD18: 3 | AE18: 2 | AF18: 2 | AG18: 3 | AH18: 3 | AI18: 4 | AJ18: 3 | AK18: 2 | AL18: 3 | AM18: 1 | AN18: 2 | AO18: 2 | AP18: 2 | AQ18: 2 | AR18: 3 | AS18: 1 | AT18: 2 | AU18: 2 | AV18: 1 | AW18: 2 | AX18: 2 | AY18: 3 | AZ18: 2 | BA18: 3 | BB18: 2 | BC18: 2 | BD18: 2 | BE18: 4 | BF18: 4 | BG18: 3 | BH18: 5 | BI18: 4 | BJ18: 4 | BK18: 4 | BL18: 4 | BM18: 5 | BN18: 4 | BO18: 4 | BP18: 4 | BQ18: 5 | BR18: 4 | BS18: =IF(COUNT(N18:W18)>=8,AVERAGE(N18:W18),"") | BT18: =IF(COUNT(X18:AE18)>=7,AVERAGE(X18:AE18),"") | BU18: =IF(COUNT(AF18:AM18)>=7,AVERAGE(AF18:AM18),"") | BV18: =IF(COUNT(AN18:AV18)>=8,AVERAGE(AN18:AV18),"") | BW18: =IF(COUNT(AW18:BD18)>=7,AVERAGE(AW18:BD18),"") | BX18: =IF(COUNT(BE18:BJ18)>=5,AVERAGE(BE18:BJ18),"") | BY18: =IF(COUNT(BK18:BR18)>=7,AVERAGE(BK18:BR18),"")
A19: P018 | B19: No | C19: Yes | D19: Female | E19: 35-44 | F19: Master's | G19: Fintech/payment provider | H19: Digital Banking/Product | I19: 16 or more | J19: Yes | K19: 1 | L19: Yes | M19: No | N19: 1 | O19: 2 | P19: 2 | Q19: 1 | R19: 2 | S19: 3 | T19: 2 | U19: 2 | V19: 3 | W19: 2 | X19: 2 | Y19: 3 | Z19: 4 | AA19: 3 | AB19: 3 | AC19: 3 | AD19: 3 | AE19: 3 | AF19: 4 | AG19: 3 | AH19: 3 | AI19: 4 | AJ19: 4 | AK19: 3 | AL19: 4 | AM19: 3 | AN19: 3 | AO19: 3 | AP19: 4 | AQ19: 3 | AR19: 4 | AS19: 4 | AT19: 3 | AU19: 2 | AV19: 3 | AW19: 4 | AX19: 3 | AY19: 4 | AZ19: 3 | BA19: 4 | BB19: 4 | BC19: 4 | BD19: 4 | BE19: 3 | BF19: 4 | BG19: 3 | BH19: 4 | BI19: 4 | BJ19: 4 | BK19: 2 | BL19: 2 | BM19: 3 | BN19: 2 | BO19: 2 | BP19: 3 | BQ19: 3 | BR19: 3 | BS19: =IF(COUNT(N19:W19)>=8,AVERAGE(N19:W19),"") | BT19: =IF(COUNT(X19:AE19)>=7,AVERAGE(X19:AE19),"") | BU19: =IF(COUNT(AF19:AM19)>=7,AVERAGE(AF19:AM19),"") | BV19: =IF(COUNT(AN19:AV19)>=8,AVERAGE(AN19:AV19),"") | BW19: =IF(COUNT(AW19:BD19)>=7,AVERAGE(AW19:BD19),"") | BX19: =IF(COUNT(BE19:BJ19)>=5,AVERAGE(BE19:BJ19),"") | BY19: =IF(COUNT(BK19:BR19)>=7,AVERAGE(BK19:BR19),"")
A20: P019 | B20: No | C20: Yes | D20: Female | E20: 25-34 | F20: Bachelor/HND | G20: Digital bank/neobank | H20: Customer Experience/Service | I20: Less than 2 | J20: Yes | K20: 1 | L20: No | M20: No | N20: 2 | O20: 3 | P20: 4 | Q20: 3 | R20: 3 | S20: 3 | T20: 2 | U20: 4 | V20: 2 | W20: 3 | X20: 2 | Y20: 2 | Z20: 4 | AA20: 2 | AB20: 3 | AC20: 2 | AD20: 2 | AE20: 3 | AF20: 2 | AG20: 3 | AH20: 2 | AI20: 4 | AJ20: 3 | AK20: 3 | AL20: 2 | AM20: 2 | AN20: 5 | AO20: 3 | AP20: 3 | AQ20: 3 | AR20: 5 | AS20: 5 | AT20: 4 | AU20: 3 | AV20: 4 | AW20: 3 | AX20: 2 | AY20: 3 | AZ20: 3 | BA20: 4 | BB20: 4 | BC20: 4 | BD20: 4 | BE20: 1 | BF20: 3 | BG20: 2 | BH20: 4 | BI20: 3 | BJ20: 3 | BK20: 2 | BL20: 2 | BM20: 2 | BN20: 3 | BO20: 4 | BP20: 3 | BQ20: 3 | BR20: 3 | BS20: =IF(COUNT(N20:W20)>=8,AVERAGE(N20:W20),"") | BT20: =IF(COUNT(X20:AE20)>=7,AVERAGE(X20:AE20),"") | BU20: =IF(COUNT(AF20:AM20)>=7,AVERAGE(AF20:AM20),"") | BV20: =IF(COUNT(AN20:AV20)>=8,AVERAGE(AN20:AV20),"") | BW20: =IF(COUNT(AW20:BD20)>=7,AVERAGE(AW20:BD20),"") | BX20: =IF(COUNT(BE20:BJ20)>=5,AVERAGE(BE20:BJ20),"") | BY20: =IF(COUNT(BK20:BR20)>=7,AVERAGE(BK20:BR20),"")
A21: P020 | B21: No | C21: Yes | D21: Male | E21: 35-44 | F21: Bachelor/HND | G21: Commercial bank | H21: Customer Experience/Service | I21: 11-15 | J21: Yes | K21: 2 | L21: Yes | M21: No | N21: 3 | O21: 2 | P21: 3 | Q21: 3 | R21: 3 | S21: 1 | T21: 2 | U21: 3 | V21: 4 | W21: 2 | X21: 4 | Y21: 4 | Z21: 5 | AA21: 3 | AB21: 4 | AC21: 3 | AD21: 3 | AE21: 3 | AF21: 4 | AG21: 4 | AH21: 3 | AI21: 5 | AJ21: 4 | AK21: 4 | AL21: 4 | AM21: 3 | AN21: 4 | AP21: 3 | AQ21: 4 | AR21: 4 | AS21: 3 | AT21: 4 | AU21: 3 | AV21: 3 | AW21: 4 | AX21: 4 | AY21: 4 | AZ21: 4 | BA21: 3 | BB21: 4 | BC21: 4 | BD21: 3 | BE21: 3 | BF21: 3 | BG21: 2 | BH21: 3 | BI21: 2 | BJ21: 2 | BK21: 3 | BL21: 2 | BN21: 3 | BO21: 3 | BP21: 3 | BQ21: 4 | BR21: 2 | BS21: =IF(COUNT(N21:W21)>=8,AVERAGE(N21:W21),"") | BT21: =IF(COUNT(X21:AE21)>=7,AVERAGE(X21:AE21),"") | BU21: =IF(COUNT(AF21:AM21)>=7,AVERAGE(AF21:AM21),"") | BV21: =IF(COUNT(AN21:AV21)>=8,AVERAGE(AN21:AV21),"") | BW21: =IF(COUNT(AW21:BD21)>=7,AVERAGE(AW21:BD21),"") | BX21: =IF(COUNT(BE21:BJ21)>=5,AVERAGE(BE21:BJ21),"") | BY21: =IF(COUNT(BK21:BR21)>=7,AVERAGE(BK21:BR21),"")
A22: P021 | B22: No | C22: Yes | D22: Female | E22: 35-44 | F22: Master's | G22: Fintech/payment provider | H22: Risk/Compliance | I22: 2-5 | J22: Yes | K22: 0 | L22: No | M22: No | N22: 3 | O22: 1 | P22: 2 | Q22: 1 | R22: 1 | S22: 1 | T22: 2 | U22: 1 | V22: 2 | W22: 1 | X22: 3 | Y22: 2 | Z22: 2 | AA22: 1 | AB22: 2 | AC22: 2 | AD22: 1 | AE22: 2 | AF22: 3 | AG22: 4 | AH22: 4 | AI22: 3 | AJ22: 3 | AK22: 3 | AL22: 3 | AM22: 4 | AN22: 4 | AO22: 3 | AP22: 4 | AQ22: 3 | AR22: 3 | AS22: 2 | AT22: 4 | AU22: 3 | AV22: 4 | AW22: 4 | AX22: 4 | AY22: 4 | AZ22: 3 | BA22: 3 | BB22: 3 | BC22: 3 | BD22: 4 | BE22: 2 | BF22: 3 | BG22: 2 | BH22: 2 | BI22: 2 | BJ22: 2 | BK22: 2 | BL22: 2 | BM22: 1 | BN22: 1 | BO22: 2 | BP22: 2 | BQ22: 3 | BR22: 1 | BS22: =IF(COUNT(N22:W22)>=8,AVERAGE(N22:W22),"") | BT22: =IF(COUNT(X22:AE22)>=7,AVERAGE(X22:AE22),"") | BU22: =IF(COUNT(AF22:AM22)>=7,AVERAGE(AF22:AM22),"") | BV22: =IF(COUNT(AN22:AV22)>=8,AVERAGE(AN22:AV22),"") | BW22: =IF(COUNT(AW22:BD22)>=7,AVERAGE(AW22:BD22),"") | BX22: =IF(COUNT(BE22:BJ22)>=5,AVERAGE(BE22:BJ22),"") | BY22: =IF(COUNT(BK22:BR22)>=7,AVERAGE(BK22:BR22),"")
A23: P022 | B23: No | C23: Yes | D23: Male | E23: 25-34 | F23: Bachelor/HND | G23: Digital bank/neobank | H23: Risk/Compliance | I23: 2-5 | J23: Yes | K23: 1 | L23: No | M23: No | N23: 2 | O23: 2 | P23: 4 | Q23: 2 | R23: 2 | S23: 2 | T23: 1 | U23: 3 | V23: 3 | W23: 2 | X23: 2 | Y23: 1 | AA23: 1 | AB23: 1 | AC23: 1 | AD23: 1 | AE23: 1 | AF23: 1 | AG23: 2 | AH23: 2 | AI23: 3 | AJ23: 3 | AK23: 3 | AL23: 2 | AM23: 2 | AO23: 2 | AP23: 3 | AQ23: 2 | AR23: 3 | AS23: 3 | AU23: 2 | AV23: 3 | AW23: 2 | AX23: 1 | AY23: 1 | BA23: 3 | BB23: 1 | BC23: 2 | BD23: 2 | BE23: 1 | BF23: 3 | BG23: 1 | BH23: 3 | BI23: 3 | BJ23: 1 | BK23: 3 | BL23: 3 | BM23: 2 | BN23: 2 | BO23: 4 | BP23: 2 | BQ23: 3 | BR23: 3 | BS23: =IF(COUNT(N23:W23)>=8,AVERAGE(N23:W23),"") | BT23: =IF(COUNT(X23:AE23)>=7,AVERAGE(X23:AE23),"") | BU23: =IF(COUNT(AF23:AM23)>=7,AVERAGE(AF23:AM23),"") | BV23: =IF(COUNT(AN23:AV23)>=8,AVERAGE(AN23:AV23),"") | BW23: =IF(COUNT(AW23:BD23)>=7,AVERAGE(AW23:BD23),"") | BX23: =IF(COUNT(BE23:BJ23)>=5,AVERAGE(BE23:BJ23),"") | BY23: =IF(COUNT(BK23:BR23)>=7,AVERAGE(BK23:BR23),"")
A24: P023 | B24: No | C24: Yes | D24: Female | E24: 25-34 | F24: Other | G24: Commercial bank | H24: Digital Banking/Product | I24: 6-10 | J24: Yes | K24: 0 | L24: No | M24: No | N24: 1 | O24: 2 | P24: 3 | Q24: 3 | R24: 2 | S24: 3 | T24: 1 | U24: 3 | V24: 3 | W24: 2 | X24: 3 | Y24: 3 | Z24: 4 | AA24: 4 | AB24: 4 | AC24: 3 | AD24: 3 | AE24: 3 | AF24: 2 | AG24: 3 | AH24: 2 | AI24: 2 | AJ24: 2 | AK24: 3 | AL24: 1 | AM24: 2 | AN24: 2 | AO24: 2 | AP24: 2 | AQ24: 2 | AR24: 2 | AS24: 3 | AT24: 3 | AU24: 2 | AV24: 3 | AW24: 4 | AX24: 2 | AY24: 2 | AZ24: 3 | BA24: 3 | BB24: 3 | BD24: 1 | BE24: 4 | BF24: 4 | BG24: 2 | BH24: 3 | BI24: 3 | BJ24: 4 | BK24: 4 | BL24: 3 | BM24: 4 | BN24: 3 | BO24: 5 | BP24: 4 | BQ24: 4 | BR24: 4 | BS24: =IF(COUNT(N24:W24)>=8,AVERAGE(N24:W24),"") | BT24: =IF(COUNT(X24:AE24)>=7,AVERAGE(X24:AE24),"") | BU24: =IF(COUNT(AF24:AM24)>=7,AVERAGE(AF24:AM24),"") | BV24: =IF(COUNT(AN24:AV24)>=8,AVERAGE(AN24:AV24),"") | BW24: =IF(COUNT(AW24:BD24)>=7,AVERAGE(AW24:BD24),"") | BX24: =IF(COUNT(BE24:BJ24)>=5,AVERAGE(BE24:BJ24),"") | BY24: =IF(COUNT(BK24:BR24)>=7,AVERAGE(BK24:BR24),"")
A25: P024 | B25: No | C25: Yes | D25: Male | E25: 35-44 | F25: Master's | G25: Commercial bank | H25: Other | I25: 2-5 | J25: Yes | K25: 1 | L25: No | M25: No | N25: 4 | O25: 4 | P25: 4 | Q25: 4 | R25: 3 | S25: 4 | T25: 4 | U25: 3 | V25: 3 | W25: 4 | X25: 3 | Y25: 4 | Z25: 3 | AA25: 4 | AB25: 3 | AC25: 4 | AD25: 4 | AE25: 4 | AF25: 3 | AG25: 3 | AH25: 3 | AJ25: 4 | AK25: 4 | AL25: 3 | AM25: 3 | AN25: 4 | AO25: 3 | AP25: 4 | AQ25: 3 | AR25: 4 | AS25: 3 | AT25: 3 | AU25: 3 | AV25: 3 | AW25: 4 | AX25: 3 | AZ25: 3 | BA25: 4 | BB25: 4 | BC25: 3 | BD25: 3 | BE25: 3 | BF25: 2 | BG25: 1 | BH25: 3 | BI25: 3 | BJ25: 2 | BK25: 3 | BL25: 1 | BM25: 2 | BN25: 2 | BO25: 2 | BP25: 2 | BQ25: 3 | BR25: 1 | BS25: =IF(COUNT(N25:W25)>=8,AVERAGE(N25:W25),"") | BT25: =IF(COUNT(X25:AE25)>=7,AVERAGE(X25:AE25),"") | BU25: =IF(COUNT(AF25:AM25)>=7,AVERAGE(AF25:AM25),"") | BV25: =IF(COUNT(AN25:AV25)>=8,AVERAGE(AN25:AV25),"") | BW25: =IF(COUNT(AW25:BD25)>=7,AVERAGE(AW25:BD25),"") | BX25: =IF(COUNT(BE25:BJ25)>=5,AVERAGE(BE25:BJ25),"") | BY25: =IF(COUNT(BK25:BR25)>=7,AVERAGE(BK25:BR25),"")
A26: P025 | B26: No | C26: Yes | D26: Male | E26: 35-44 | F26: Diploma/OND/NCE | G26: Commercial bank | H26: Other | I26: Less than 2 | J26: Yes | K26: 1 | L26: No | M26: No | O26: 5 | P26: 5 | Q26: 3 | R26: 3 | S26: 4 | T26: 3 | U26: 5 | V26: 5 | W26: 4 | X26: 4 | Y26: 2 | Z26: 3 | AA26: 1 | AB26: 3 | AC26: 3 | AD26: 2 | AE26: 3 | AF26: 3 | AG26: 3 | AH26: 1 | AI26: 2 | AJ26: 2 | AL26: 1 | AM26: 2 | AN26: 3 | AO26: 2 | AP26: 3 | AQ26: 3 | AR26: 3 | AS26: 1 | AT26: 2 | AU26: 2 | AV26: 3 | AW26: 3 | AX26: 2 | AY26: 1 | AZ26: 2 | BA26: 2 | BB26: 3 | BC26: 2 | BD26: 1 | BE26: 3 | BF26: 5 | BG26: 3 | BH26: 3 | BI26: 4 | BJ26: 3 | BK26: 4 | BL26: 4 | BM26: 5 | BN26: 3 | BO26: 4 | BP26: 4 | BQ26: 4 | BR26: 5 | BS26: =IF(COUNT(N26:W26)>=8,AVERAGE(N26:W26),"") | BT26: =IF(COUNT(X26:AE26)>=7,AVERAGE(X26:AE26),"") | BU26: =IF(COUNT(AF26:AM26)>=7,AVERAGE(AF26:AM26),"") | BV26: =IF(COUNT(AN26:AV26)>=8,AVERAGE(AN26:AV26),"") | BW26: =IF(COUNT(AW26:BD26)>=7,AVERAGE(AW26:BD26),"") | BX26: =IF(COUNT(BE26:BJ26)>=5,AVERAGE(BE26:BJ26),"") | BY26: =IF(COUNT(BK26:BR26)>=7,AVERAGE(BK26:BR26),"")
A27: P026 | B27: No | C27: Yes | D27: Female | E27: 35-44 | F27: Diploma/OND/NCE | G27: Microfinance bank | H27: Relationship/Marketing | I27: 6-10 | J27: Yes | K27: 1 | L27: Yes | M27: No | N27: 5 | O27: 4 | P27: 5 | Q27: 3 | R27: 5 | S27: 5 | T27: 4 | U27: 4 | V27: 4 | W27: 4 | X27: 4 | Y27: 4 | Z27: 5 | AA27: 5 | AB27: 4 | AC27: 5 | AD27: 4 | AE27: 5 | AF27: 4 | AG27: 4 | AH27: 3 | AI27: 3 | AJ27: 4 | AK27: 4 | AL27: 3 | AM27: 4 | AN27: 5 | AO27: 4 | AP27: 5 | AQ27: 5 | AR27: 5 | AS27: 5 | AT27: 4 | AU27: 5 | AV27: 4 | AW27: 5 | AX27: 4 | AY27: 5 | AZ27: 3 | BA27: 4 | BB27: 3 | BC27: 4 | BD27: 4 | BE27: 3 | BF27: 3 | BG27: 2 | BH27: 4 | BI27: 3 | BJ27: 3 | BK27: 2 | BL27: 2 | BM27: 3 | BN27: 2 | BO27: 3 | BP27: 3 | BQ27: 3 | BR27: 2 | BS27: =IF(COUNT(N27:W27)>=8,AVERAGE(N27:W27),"") | BT27: =IF(COUNT(X27:AE27)>=7,AVERAGE(X27:AE27),"") | BU27: =IF(COUNT(AF27:AM27)>=7,AVERAGE(AF27:AM27),"") | BV27: =IF(COUNT(AN27:AV27)>=8,AVERAGE(AN27:AV27),"") | BW27: =IF(COUNT(AW27:BD27)>=7,AVERAGE(AW27:BD27),"") | BX27: =IF(COUNT(BE27:BJ27)>=5,AVERAGE(BE27:BJ27),"") | BY27: =IF(COUNT(BK27:BR27)>=7,AVERAGE(BK27:BR27),"")
A28: P027 | B28: No | C28: Yes | D28: Female | E28: 25-34 | F28: Bachelor/HND | G28: Digital bank/neobank | H28: IT/Technology | I28: 16 or more | J28: Yes | K28: 0 | L28: No | M28: No | N28: 3 | O28: 2 | P28: 3 | Q28: 2 | R28: 2 | S28: 4 | T28: 3 | U28: 3 | V28: 3 | W28: 3 | X28: 3 | Y28: 2 | Z28: 2 | AA28: 2 | AB28: 3 | AC28: 3 | AD28: 4 | AE28: 3 | AF28: 1 | AG28: 3 | AH28: 3 | AI28: 3 | AJ28: 3 | AK28: 3 | AL28: 2 | AM28: 2 | AN28: 2 | AO28: 2 | AP28: 2 | AQ28: 3 | AR28: 2 | AS28: 2 | AT28: 3 | AV28: 3 | AW28: 2 | AX28: 2 | AY28: 3 | AZ28: 2 | BA28: 3 | BB28: 3 | BC28: 2 | BD28: 2 | BE28: 3 | BF28: 3 | BG28: 3 | BH28: 3 | BI28: 2 | BJ28: 3 | BK28: 2 | BL28: 4 | BM28: 4 | BN28: 3 | BO28: 4 | BP28: 4 | BQ28: 3 | BR28: 3 | BS28: =IF(COUNT(N28:W28)>=8,AVERAGE(N28:W28),"") | BT28: =IF(COUNT(X28:AE28)>=7,AVERAGE(X28:AE28),"") | BU28: =IF(COUNT(AF28:AM28)>=7,AVERAGE(AF28:AM28),"") | BV28: =IF(COUNT(AN28:AV28)>=8,AVERAGE(AN28:AV28),"") | BW28: =IF(COUNT(AW28:BD28)>=7,AVERAGE(AW28:BD28),"") | BX28: =IF(COUNT(BE28:BJ28)>=5,AVERAGE(BE28:BJ28),"") | BY28: =IF(COUNT(BK28:BR28)>=7,AVERAGE(BK28:BR28),"")
A29: P028 | B29: No | C29: Yes | D29: Male | E29: 45-54 | F29: Bachelor/HND | G29: Commercial bank | H29: Management/Strategy | I29: 2-5 | J29: Yes | K29: 3 | L29: Yes | M29: No | N29: 3 | O29: 3 | P29: 3 | Q29: 3 | R29: 2 | S29: 4 | T29: 3 | U29: 3 | V29: 5 | W29: 3 | X29: 4 | Z29: 4 | AA29: 4 | AB29: 3 | AC29: 4 | AD29: 4 | AE29: 3 | AF29: 4 | AG29: 4 | AH29: 4 | AI29: 5 | AJ29: 4 | AK29: 5 | AL29: 5 | AM29: 4 | AN29: 4 | AO29: 3 | AP29: 3 | AQ29: 4 | AR29: 4 | AS29: 3 | AT29: 4 | AU29: 3 | AV29: 3 | AW29: 5 | AY29: 5 | AZ29: 4 | BA29: 5 | BB29: 5 | BC29: 3 | BD29: 4 | BE29: 4 | BF29: 3 | BG29: 4 | BH29: 5 | BI29: 5 | BJ29: 3 | BK29: 4 | BL29: 2 | BM29: 4 | BN29: 4 | BO29: 3 | BP29: 3 | BQ29: 5 | BR29: 2 | BS29: =IF(COUNT(N29:W29)>=8,AVERAGE(N29:W29),"") | BT29: =IF(COUNT(X29:AE29)>=7,AVERAGE(X29:AE29),"") | BU29: =IF(COUNT(AF29:AM29)>=7,AVERAGE(AF29:AM29),"") | BV29: =IF(COUNT(AN29:AV29)>=8,AVERAGE(AN29:AV29),"") | BW29: =IF(COUNT(AW29:BD29)>=7,AVERAGE(AW29:BD29),"") | BX29: =IF(COUNT(BE29:BJ29)>=5,AVERAGE(BE29:BJ29),"") | BY29: =IF(COUNT(BK29:BR29)>=7,AVERAGE(BK29:BR29),"")
A30: P029 | B30: No | C30: Yes | D30: Female | E30: 55 or above | F30: Bachelor/HND | G30: Insurance/investment/other licensed financial institution | H30: Customer Experience/Service | I30: Less than 2 | J30: Yes | K30: 3 | L30: Yes | M30: No | N30: 4 | O30: 5 | P30: 5 | Q30: 5 | R30: 4 | S30: 4 | T30: 5 | U30: 4 | V30: 5 | W30: 4 | X30: 5 | Y30: 4 | Z30: 4 | AA30: 3 | AB30: 4 | AC30: 4 | AD30: 4 | AE30: 4 | AF30: 4 | AG30: 2 | AH30: 2 | AI30: 3 | AJ30: 4 | AK30: 3 | AL30: 3 | AM30: 4 | AN30: 5 | AO30: 3 | AP30: 5 | AR30: 5 | AS30: 5 | AT30: 4 | AU30: 3 | AV30: 4 | AW30: 3 | AX30: 3 | AY30: 5 | AZ30: 3 | BA30: 4 | BB30: 4 | BC30: 4 | BD30: 3 | BE30: 3 | BF30: 4 | BG30: 3 | BH30: 3 | BI30: 3 | BJ30: 4 | BK30: 4 | BL30: 2 | BM30: 3 | BN30: 2 | BO30: 3 | BP30: 2 | BQ30: 2 | BR30: 2 | BS30: =IF(COUNT(N30:W30)>=8,AVERAGE(N30:W30),"") | BT30: =IF(COUNT(X30:AE30)>=7,AVERAGE(X30:AE30),"") | BU30: =IF(COUNT(AF30:AM30)>=7,AVERAGE(AF30:AM30),"") | BV30: =IF(COUNT(AN30:AV30)>=8,AVERAGE(AN30:AV30),"") | BW30: =IF(COUNT(AW30:BD30)>=7,AVERAGE(AW30:BD30),"") | BX30: =IF(COUNT(BE30:BJ30)>=5,AVERAGE(BE30:BJ30),"") | BY30: =IF(COUNT(BK30:BR30)>=7,AVERAGE(BK30:BR30),"")
A31: P030 | B31: No | C31: Yes | D31: Female | E31: 35-44 | F31: Diploma/OND/NCE | G31: Merchant bank | H31: Digital Banking/Product | I31: 11-15 | J31: Yes | K31: 1 | L31: No | M31: No | N31: 2 | O31: 3 | P31: 3 | Q31: 1 | R31: 4 | S31: 4 | T31: 3 | U31: 3 | V31: 3 | W31: 1 | X31: 4 | Y31: 3 | AA31: 2 | AB31: 3 | AC31: 3 | AD31: 4 | AE31: 4 | AF31: 2 | AG31: 3 | AH31: 3 | AI31: 2 | AJ31: 4 | AK31: 3 | AL31: 4 | AM31: 3 | AN31: 4 | AO31: 4 | AP31: 3 | AQ31: 3 | AR31: 4 | AS31: 3 | AT31: 3 | AU31: 3 | AV31: 4 | AW31: 4 | AX31: 4 | AY31: 3 | AZ31: 3 | BA31: 3 | BB31: 3 | BC31: 3 | BD31: 2 | BE31: 2 | BF31: 3 | BG31: 2 | BH31: 3 | BJ31: 2 | BK31: 2 | BL31: 2 | BM31: 4 | BN31: 3 | BO31: 2 | BP31: 4 | BQ31: 4 | BR31: 2 | BS31: =IF(COUNT(N31:W31)>=8,AVERAGE(N31:W31),"") | BT31: =IF(COUNT(X31:AE31)>=7,AVERAGE(X31:AE31),"") | BU31: =IF(COUNT(AF31:AM31)>=7,AVERAGE(AF31:AM31),"") | BV31: =IF(COUNT(AN31:AV31)>=8,AVERAGE(AN31:AV31),"") | BW31: =IF(COUNT(AW31:BD31)>=7,AVERAGE(AW31:BD31),"") | BX31: =IF(COUNT(BE31:BJ31)>=5,AVERAGE(BE31:BJ31),"") | BY31: =IF(COUNT(BK31:BR31)>=7,AVERAGE(BK31:BR31),"")
A32: R001 | B32: No | C32: No | D32: Male | E32: 18-24 | F32: Master's | G32: Commercial bank | H32: Customer Experience/Service | I32: 2-5 | J32: Yes | K32: 4 | L32: Yes | M32: Yes | N32: 3 | O32: 4 | P32: 5 | Q32: 5 | R32: 4 | S32: 3 | T32: 3 | U32: 4 | V32: 4 | W32: 4 | X32: 3 | Y32: 1 | Z32: 2 | AA32: 3 | AB32: 3 | AC32: 2 | AD32: 2 | AE32: 2 | AF32: 3 | AG32: 3 | AH32: 2 | AI32: 2 | AJ32: 2 | AK32: 3 | AL32: 2 | AM32: 2 | AN32: 1 | AO32: 1 | AP32: 1 | AQ32: 1 | AR32: 1 | AS32: 1 | AT32: 2 | AU32: 1 | AV32: 2 | AW32: 1 | AX32: 1 | AY32: 2 | AZ32: 1 | BA32: 2 | BB32: 2 | BC32: 1 | BD32: 1 | BE32: 4 | BF32: 4 | BG32: 3 | BH32: 4 | BI32: 2 | BJ32: 4 | BK32: 3 | BL32: 3 | BM32: 4 | BN32: 3 | BO32: 5 | BP32: 5 | BQ32: 4 | BR32: 4 | BS32: =IF(COUNT(N32:W32)>=8,AVERAGE(N32:W32),"") | BT32: =IF(COUNT(X32:AE32)>=7,AVERAGE(X32:AE32),"") | BU32: =IF(COUNT(AF32:AM32)>=7,AVERAGE(AF32:AM32),"") | BV32: =IF(COUNT(AN32:AV32)>=8,AVERAGE(AN32:AV32),"") | BW32: =IF(COUNT(AW32:BD32)>=7,AVERAGE(AW32:BD32),"") | BX32: =IF(COUNT(BE32:BJ32)>=5,AVERAGE(BE32:BJ32),"") | BY32: =IF(COUNT(BK32:BR32)>=7,AVERAGE(BK32:BR32),"")
A33: R002 | B33: No | C33: No | D33: Male | E33: 35-44 | F33: Master's | G33: Commercial bank | H33: Risk/Compliance | I33: 11-15 | J33: Yes | K33: 0 | L33: No | M33: Yes | N33: 2 | O33: 2 | P33: 3 | Q33: 2 | R33: 2 | S33: 3 | T33: 1 | V33: 2 | W33: 2 | X33: 2 | Y33: 1 | Z33: 2 | AA33: 1 | AC33: 2 | AD33: 2 | AE33: 2 | AF33: 1 | AG33: 1 | AH33: 2 | AI33: 2 | AJ33: 1 | AK33: 2 | AL33: 2 | AM33: 2 | AN33: 3 | AO33: 2 | AP33: 2 | AQ33: 2 | AR33: 3 | AS33: 3 | AT33: 2 | AU33: 2 | AV33: 4 | AW33: 2 | AX33: 1 | AY33: 2 | AZ33: 2 | BA33: 3 | BB33: 2 | BC33: 2 | BD33: 2 | BE33: 3 | BF33: 3 | BG33: 2 | BH33: 3 | BI33: 3 | BK33: 5 | BL33: 4 | BM33: 5 | BN33: 4 | BO33: 5 | BP33: 3 | BQ33: 5 | BR33: 4 | BS33: =IF(COUNT(N33:W33)>=8,AVERAGE(N33:W33),"") | BT33: =IF(COUNT(X33:AE33)>=7,AVERAGE(X33:AE33),"") | BU33: =IF(COUNT(AF33:AM33)>=7,AVERAGE(AF33:AM33),"") | BV33: =IF(COUNT(AN33:AV33)>=8,AVERAGE(AN33:AV33),"") | BW33: =IF(COUNT(AW33:BD33)>=7,AVERAGE(AW33:BD33),"") | BX33: =IF(COUNT(BE33:BJ33)>=5,AVERAGE(BE33:BJ33),"") | BY33: =IF(COUNT(BK33:BR33)>=7,AVERAGE(BK33:BR33),"")
A34: R003 | B34: No | C34: No | D34: Female | E34: 35-44 | F34: Bachelor/HND | G34: Fintech/payment provider | H34: Customer Experience/Service | I34: 6-10 | J34: Yes | K34: 3 | L34: Yes | M34: Yes | N34: 2 | O34: 1 | P34: 3 | Q34: 1 | R34: 3 | S34: 2 | T34: 3 | U34: 4 | V34: 2 | W34: 4 | X34: 3 | Y34: 3 | Z34: 3 | AA34: 2 | AB34: 2 | AC34: 3 | AD34: 2 | AE34: 2 | AF34: 3 | AG34: 3 | AH34: 2 | AI34: 3 | AJ34: 2 | AK34: 3 | AM34: 3 | AN34: 3 | AO34: 3 | AP34: 5 | AQ34: 3 | AR34: 4 | AS34: 3 | AT34: 4 | AU34: 3 | AV34: 3 | AW34: 3 | AX34: 2 | AY34: 2 | AZ34: 2 | BA34: 3 | BB34: 4 | BC34: 2 | BD34: 2 | BE34: 2 | BF34: 2 | BG34: 1 | BH34: 3 | BI34: 3 | BJ34: 3 | BK34: 1 | BL34: 3 | BM34: 2 | BN34: 2 | BP34: 2 | BQ34: 4 | BR34: 2 | BS34: =IF(COUNT(N34:W34)>=8,AVERAGE(N34:W34),"") | BT34: =IF(COUNT(X34:AE34)>=7,AVERAGE(X34:AE34),"") | BU34: =IF(COUNT(AF34:AM34)>=7,AVERAGE(AF34:AM34),"") | BV34: =IF(COUNT(AN34:AV34)>=8,AVERAGE(AN34:AV34),"") | BW34: =IF(COUNT(AW34:BD34)>=7,AVERAGE(AW34:BD34),"") | BX34: =IF(COUNT(BE34:BJ34)>=5,AVERAGE(BE34:BJ34),"") | BY34: =IF(COUNT(BK34:BR34)>=7,AVERAGE(BK34:BR34),"")
A35: R004 | B35: No | C35: No | D35: Male | E35: 35-44 | F35: Bachelor/HND | G35: Commercial bank | H35: Relationship/Marketing | I35: 2-5 | J35: Yes | K35: 1 | L35: No | M35: Yes | N35: 3 | O35: 3 | P35: 4 | Q35: 4 | R35: 3 | S35: 4 | T35: 3 | U35: 4 | V35: 4 | W35: 4 | X35: 4 | Y35: 5 | Z35: 5 | AA35: 3 | AB35: 4 | AC35: 4 | AD35: 5 | AE35: 4 | AF35: 3 | AG35: 3 | AH35: 4 | AI35: 4 | AJ35: 4 | AK35: 4 | AL35: 5 | AM35: 3 | AN35: 3 | AO35: 4 | AP35: 5 | AQ35: 4 | AR35: 3 | AS35: 3 | AT35: 4 | AU35: 4 | AV35: 4 | AW35: 3 | AX35: 2 | AY35: 4 | AZ35: 3 | BA35: 4 | BB35: 3 | BC35: 3 | BD35: 3 | BE35: 3 | BF35: 2 | BG35: 2 | BH35: 2 | BI35: 4 | BJ35: 4 | BK35: 3 | BL35: 2 | BN35: 3 | BO35: 3 | BP35: 2 | BQ35: 2 | BR35: 2 | BS35: =IF(COUNT(N35:W35)>=8,AVERAGE(N35:W35),"") | BT35: =IF(COUNT(X35:AE35)>=7,AVERAGE(X35:AE35),"") | BU35: =IF(COUNT(AF35:AM35)>=7,AVERAGE(AF35:AM35),"") | BV35: =IF(COUNT(AN35:AV35)>=8,AVERAGE(AN35:AV35),"") | BW35: =IF(COUNT(AW35:BD35)>=7,AVERAGE(AW35:BD35),"") | BX35: =IF(COUNT(BE35:BJ35)>=5,AVERAGE(BE35:BJ35),"") | BY35: =IF(COUNT(BK35:BR35)>=7,AVERAGE(BK35:BR35),"")
A36: R005 | B36: No | C36: No | D36: Male | E36: 25-34 | F36: Bachelor/HND | G36: Microfinance bank | H36: Risk/Compliance | I36: 6-10 | J36: Yes | K36: 0 | L36: Do not know | M36: Yes | N36: 4 | O36: 3 | P36: 4 | Q36: 3 | R36: 3 | S36: 3 | T36: 4 | U36: 3 | V36: 4 | W36: 2 | X36: 2 | Y36: 3 | Z36: 2 | AA36: 2 | AB36: 1 | AC36: 3 | AD36: 2 | AE36: 1 | AG36: 2 | AH36: 2 | AI36: 3 | AJ36: 3 | AK36: 3 | AL36: 3 | AM36: 2 | AN36: 3 | AO36: 3 | AP36: 3 | AQ36: 3 | AR36: 3 | AS36: 3 | AT36: 3 | AU36: 2 | AV36: 3 | AW36: 4 | AX36: 2 | AY36: 2 | AZ36: 1 | BA36: 5 | BB36: 3 | BC36: 3 | BD36: 2 | BE36: 2 | BF36: 2 | BG36: 3 | BH36: 3 | BI36: 2 | BJ36: 4 | BK36: 4 | BL36: 3 | BM36: 5 | BN36: 3 | BO36: 4 | BP36: 5 | BQ36: 4 | BR36: 3 | BS36: =IF(COUNT(N36:W36)>=8,AVERAGE(N36:W36),"") | BT36: =IF(COUNT(X36:AE36)>=7,AVERAGE(X36:AE36),"") | BU36: =IF(COUNT(AF36:AM36)>=7,AVERAGE(AF36:AM36),"") | BV36: =IF(COUNT(AN36:AV36)>=8,AVERAGE(AN36:AV36),"") | BW36: =IF(COUNT(AW36:BD36)>=7,AVERAGE(AW36:BD36),"") | BX36: =IF(COUNT(BE36:BJ36)>=5,AVERAGE(BE36:BJ36),"") | BY36: =IF(COUNT(BK36:BR36)>=7,AVERAGE(BK36:BR36),"")
A37: R006 | B37: No | C37: Yes | D37: Female | E37: 25-34 | F37: Bachelor/HND | G37: Insurance/investment/other licensed financial institution | H37: Risk/Compliance | I37: 2-5 | J37: Yes | K37: 3 | L37: Yes | M37: No | N37: 4 | O37: 3 | P37: 3 | Q37: 2 | R37: 2 | S37: 4 | T37: 2 | U37: 3 | V37: 3 | W37: 3 | X37: 4 | Y37: 4 | Z37: 4 | AA37: 4 | AB37: 4 | AC37: 4 | AD37: 5 | AE37: 4 | AF37: 2 | AG37: 4 | AH37: 2 | AI37: 4 | AJ37: 3 | AK37: 3 | AL37: 4 | AM37: 3 | AN37: 4 | AO37: 4 | AP37: 3 | AQ37: 3 | AR37: 5 | AS37: 4 | AT37: 3 | AU37: 3 | AV37: 5 | AW37: 5 | AX37: 2 | AY37: 3 | AZ37: 3 | BA37: 3 | BB37: 3 | BC37: 3 | BD37: 3 | BE37: 4 | BF37: 3 | BG37: 4 | BH37: 4 | BJ37: 3 | BK37: 3 | BL37: 2 | BM37: 3 | BN37: 3 | BO37: 2 | BP37: 3 | BQ37: 2 | BR37: 3 | BS37: =IF(COUNT(N37:W37)>=8,AVERAGE(N37:W37),"") | BT37: =IF(COUNT(X37:AE37)>=7,AVERAGE(X37:AE37),"") | BU37: =IF(COUNT(AF37:AM37)>=7,AVERAGE(AF37:AM37),"") | BV37: =IF(COUNT(AN37:AV37)>=8,AVERAGE(AN37:AV37),"") | BW37: =IF(COUNT(AW37:BD37)>=7,AVERAGE(AW37:BD37),"") | BX37: =IF(COUNT(BE37:BJ37)>=5,AVERAGE(BE37:BJ37),"") | BY37: =IF(COUNT(BK37:BR37)>=7,AVERAGE(BK37:BR37),"")
A38: R007 | B38: No | C38: Yes | D38: Female | E38: 35-44 | F38: Bachelor/HND | G38: Digital bank/neobank | H38: Relationship/Marketing | I38: 2-5 | J38: Yes | K38: 0 | L38: Yes | M38: No | N38: 3 | O38: 3 | P38: 3 | Q38: 3 | R38: 4 | S38: 4 | T38: 4 | U38: 3 | V38: 5 | W38: 4 | X38: 4 | Y38: 3 | Z38: 4 | AA38: 3 | AB38: 3 | AC38: 4 | AD38: 5 | AE38: 3 | AF38: 4 | AG38: 4 | AH38: 2 | AI38: 4 | AJ38: 3 | AK38: 5 | AL38: 2 | AM38: 4 | AN38: 4 | AO38: 2 | AP38: 3 | AQ38: 3 | AR38: 4 | AS38: 2 | AT38: 2 | AU38: 3 | AV38: 3 | AW38: 5 | AX38: 3 | AY38: 4 | AZ38: 5 | BA38: 4 | BB38: 4 | BC38: 3 | BD38: 3 | BE38: 3 | BF38: 3 | BG38: 2 | BH38: 3 | BI38: 2 | BJ38: 3 | BK38: 3 | BL38: 3 | BM38: 2 | BN38: 2 | BO38: 3 | BP38: 2 | BQ38: 4 | BR38: 1 | BS38: =IF(COUNT(N38:W38)>=8,AVERAGE(N38:W38),"") | BT38: =IF(COUNT(X38:AE38)>=7,AVERAGE(X38:AE38),"") | BU38: =IF(COUNT(AF38:AM38)>=7,AVERAGE(AF38:AM38),"") | BV38: =IF(COUNT(AN38:AV38)>=8,AVERAGE(AN38:AV38),"") | BW38: =IF(COUNT(AW38:BD38)>=7,AVERAGE(AW38:BD38),"") | BX38: =IF(COUNT(BE38:BJ38)>=5,AVERAGE(BE38:BJ38),"") | BY38: =IF(COUNT(BK38:BR38)>=7,AVERAGE(BK38:BR38),"")
A39: R008 | B39: No | C39: Yes | D39: Female | E39: 25-34 | F39: Bachelor/HND | G39: Digital bank/neobank | H39: Relationship/Marketing | I39: 6-10 | J39: Yes | K39: 3 | L39: No | M39: No | N39: 3 | O39: 2 | P39: 3 | Q39: 3 | R39: 3 | S39: 3 | T39: 3 | U39: 2 | V39: 3 | W39: 4 | X39: 3 | Y39: 3 | Z39: 3 | AA39: 3 | AB39: 3 | AC39: 4 | AD39: 3 | AE39: 3 | AF39: 3 | AG39: 4 | AH39: 3 | AI39: 3 | AJ39: 3 | AK39: 4 | AL39: 4 | AM39: 4 | AN39: 4 | AO39: 3 | AP39: 5 | AQ39: 3 | AS39: 4 | AT39: 5 | AU39: 4 | AV39: 4 | AW39: 4 | AX39: 3 | AY39: 4 | AZ39: 4 | BA39: 4 | BB39: 3 | BC39: 4 | BD39: 4 | BE39: 4 | BF39: 3 | BG39: 4 | BH39: 5 | BI39: 4 | BJ39: 3 | BK39: 3 | BL39: 3 | BM39: 4 | BN39: 2 | BO39: 3 | BP39: 4 | BQ39: 3 | BR39: 3 | BS39: =IF(COUNT(N39:W39)>=8,AVERAGE(N39:W39),"") | BT39: =IF(COUNT(X39:AE39)>=7,AVERAGE(X39:AE39),"") | BU39: =IF(COUNT(AF39:AM39)>=7,AVERAGE(AF39:AM39),"") | BV39: =IF(COUNT(AN39:AV39)>=8,AVERAGE(AN39:AV39),"") | BW39: =IF(COUNT(AW39:BD39)>=7,AVERAGE(AW39:BD39),"") | BX39: =IF(COUNT(BE39:BJ39)>=5,AVERAGE(BE39:BJ39),"") | BY39: =IF(COUNT(BK39:BR39)>=7,AVERAGE(BK39:BR39),"")
A40: R009 | B40: Yes | C40: Yes | D40: Male | E40: 25-34 | F40: Master's | G40: Microfinance bank | H40: Relationship/Marketing | I40: 6-10 | J40: Yes | K40: 2 | L40: Yes | M40: Yes | N40: 2 | O40: 3 | P40: 2 | Q40: 1 | R40: 1 | S40: 3 | T40: 2 | U40: 1 | V40: 3 | W40: 2 | X40: 4 | Y40: 3 | Z40: 4 | AA40: 3 | AB40: 3 | AC40: 3 | AD40: 3 | AE40: 3 | AF40: 3 | AG40: 4 | AH40: 3 | AI40: 4 | AJ40: 4 | AK40: 2 | AL40: 3 | AM40: 3 | AN40: 4 | AO40: 3 | AP40: 4 | AQ40: 4 | AR40: 3 | AS40: 4 | AT40: 4 | AU40: 3 | AV40: 5 | AW40: 4 | AX40: 4 | AY40: 3 | AZ40: 3 | BA40: 5 | BB40: 4 | BC40: 3 | BD40: 3 | BE40: 2 | BF40: 3 | BG40: 2 | BH40: 3 | BI40: 2 | BJ40: 1 | BK40: 4 | BL40: 4 | BM40: 4 | BN40: 4 | BO40: 4 | BP40: 4 | BQ40: 4 | BR40: 2 | BS40: =IF(COUNT(N40:W40)>=8,AVERAGE(N40:W40),"") | BT40: =IF(COUNT(X40:AE40)>=7,AVERAGE(X40:AE40),"") | BU40: =IF(COUNT(AF40:AM40)>=7,AVERAGE(AF40:AM40),"") | BV40: =IF(COUNT(AN40:AV40)>=8,AVERAGE(AN40:AV40),"") | BW40: =IF(COUNT(AW40:BD40)>=7,AVERAGE(AW40:BD40),"") | BX40: =IF(COUNT(BE40:BJ40)>=5,AVERAGE(BE40:BJ40),"") | BY40: =IF(COUNT(BK40:BR40)>=7,AVERAGE(BK40:BR40),"")
...

Sheet Response_Tracker
A1: RESPONSE COLLECTION TRACKER
A3: Metric | B3: Value | D3: AI Maturity Group | E3: Code | F3: Valid N
A4: Main sample target | B4: 420 | D4: None | E4: 0 | F4: =COUNTIFS(Raw_Data!$B$2:$B$501,"Yes",Raw_Data!$K$2:$K$501,E4)
A5: Pilot target | B5: 30 | D5: Exploratory/pilot | E5: 1 | F5: =COUNTIFS(Raw_Data!$B$2:$B$501,"Yes",Raw_Data!$K$2:$K$501,E5)
A6: Records entered | B6: =COUNTIF(Raw_Data!C2:C501,"<>") | D6: Limited deployment | E6: 2 | F6: =COUNTIFS(Raw_Data!$B$2:$B$501,"Yes",Raw_Data!$K$2:$K$501,E6)
A7: Marked valid | B7: =COUNTIF(Raw_Data!B2:B501,"Yes") | D7: Established multi-use-case | E7: 3 | F7: =COUNTIFS(Raw_Data!$B$2:$B$501,"Yes",Raw_Data!$K$2:$K$501,E7)
A8: Remaining to target | B8: =MAX(B4-B7,0) | D8: Advanced/enterprise-wide | E8: 4 | F8: =COUNTIFS(Raw_Data!$B$2:$B$501,"Yes",Raw_Data!$K$2:$K$501,E8)
A9: Completion % | B9: =IF(B4=0,0,B7/B4)
A10: Last updated | B10: 46277.594

Sheet Analysis_Map
A1: Objective | B1: Research Question | C1: Variables | D1: Analysis | E1: Hypothesis | F1: Expected Output
A2: 1 | B2: What factors influence customer churn? | C2: CHD1-CHD10; CHD_Mean | D2: Frequencies, %, mean, SD; rank items by mean | E2: No formal hypothesis | F2: Ranked churn determinants
A3: 2 | B3: How can AI be applied to churn prediction? | C3: AIA1-AIA8; PAC1-PAC8 | D3: Descriptives + Pearson AIA_Mean vs PAC_Mean | E3: H01 | F3: Correlation table + interpretation
A4: 3 | B4: Which AI techniques are most suitable? | C4: MLU1-MLU9 | D4: Descriptives; rank by mean | E4: No formal hypothesis | F4: Technique suitability table
A5: 4 | B5: How effective are AI-driven models in reducing attrition? | C5: PAC; CRE; A8 | D5: Descriptives + one-way ANOVA | E5: H03 | F5: Group means, Levene, ANOVA, effect size/post-hoc
A6: 5 | B6: How do AI insights contribute to retention optimization? | C6: AIA; PAC; MLU; RSO | D6: Multiple regression | E6: H02 | F6: Model summary, ANOVA, coefficient table
A7: 6 | B7: What framework supports implementation? | C7: IMP1-IMP8 + interview themes | D7: Descriptive + thematic + mixed-method synthesis | E7: Framework objective | F7: Implementation framework / joint display

Sheet Pilot_Reliability
A1: Construct | B1: Item Codes | C1: No. Items | D1: Observed Cronbach Alpha | E1: Threshold | F1: Decision
A2: CHD | B2: CHD1-CHD10 | C2: 10 | D2: 0.93 | E2: 0.7 | F2: Accept (alpha>=0.70, SYNTHETIC)
A3: AIA | B3: AIA1-AIA8 | C3: 8 | D3: 0.912 | E3: 0.7 | F3: Accept (alpha>=0.70, SYNTHETIC)
A4: PAC | B4: PAC1-PAC8 | C4: 8 | D4: 0.864 | E4: 0.7 | F4: Accept (alpha>=0.70, SYNTHETIC)
A5: MLU | B5: MLU1-MLU9 | C5: 9 | D5: 0.931 | E5: 0.7 | F5: Accept (alpha>=0.70, SYNTHETIC)
A6: RSO | B6: RSO1-RSO8 | C6: 8 | D6: 0.93 | E6: 0.7 | F6: Accept (alpha>=0.70, SYNTHETIC)
A7: CRE | B7: CRE1-CRE6 | C7: 6 | D7: 0.852 | E7: 0.7 | F7: Accept (alpha>=0.70, SYNTHETIC)
A8: IMP | B8: IMP1-IMP8 | C8: 8 | D8: 0.846 | E8: 0.7 | F8: Accept (alpha>=0.70, SYNTHETIC)
A10: Pilot rule
A11: Use approximately 30 eligible professionals outside the main study area. Do not combine pilot responses with the main sample.
A12: Review alpha together with item-total statistics and conceptual coverage; do not delete an item only to raise alpha.
A13: Freeze wording after supervisor approval before main data collection.

Sheet Interview_Coding
A1: Participant_ID | B1: Role | C1: Interview_Date | D1: Question_Code | E1: Initial_Code | F1: Candidate_Theme | G1: Final_Theme | H1: Supporting_Quote | I1: Quant_Finding_Link | J1: Integration_Type | K1: Analyst_Note
A2: P01 | B2: Digital Banking Manager | C2: 2026-07-19 | D2: IQ1 | E2: IQ1: churn drivers observed in practice - service improvement noted | F2: Service improvement | G2: Service improvement | H2: "Measure saved relationships, not just model AUC." [SYNTHETIC] | I2: Direct churn-reduction M=2.94 | J2: Complements | K2: SYNTHETIC demo coding for methods illustration.
A3: P01 | B3: Digital Banking Manager | C3: 2026-07-21 | D3: IQ2 | E3: IQ2: silent churn / multi-banking signs - enterprise ownership noted | F3: Enterprise ownership | G3: Enterprise ownership | H3: "RACI and a weekly review beat another model tweak." [SYNTHETIC] | I3: Cross-functional ownership M=3.42 | J3: Converges | K3: SYNTHETIC demo coding for methods illustration.
A4: P01 | B4: Digital Banking Manager | C4: 2026-07-02 | D4: IQ3 | E4: IQ3: AI use for behavioural monitoring - enterprise ownership noted | F4: Enterprise ownership | G4: Enterprise ownership | H4: "Retention fails when it belongs to nobody; it needs business, data, tech and CX at one table." [SYNTHETIC] | I4: Cross-functional ownership M=3.42 | J4: Converges | K4: SYNTHETIC demo coding for methods illustration.
A5: P01 | B5: Digital Banking Manager | C5: 2026-07-24 | D5: IQ4 | E5: IQ4: risk scoring and early warning - early warning noted | F5: Early warning | G5: Early warning | H5: "The model can identify a customer who is likely to leave, but if the bank does nothing with that information, the prediction has no commercial value." [P03 seed paraphrase - SYNTHETIC] [SYNTHETIC] | I5: Risk scoring M=3.38 | J5: Converges | K5: SYNTHETIC demo coding for methods illustration.
A6: P01 | B6: Digital Banking Manager | C6: 2026-07-14 | D6: IQ5 | E6: IQ5: explainability and reason codes - service improvement noted | F6: Service improvement | G6: Service improvement | H6: "No model compensates for persistent downtime - fix service, then optimize offers." [SYNTHETIC] | I6: Direct churn-reduction M=2.94 | J6: Complements | K6: SYNTHETIC demo coding for methods illustration.
A7: P01 | B7: Digital Banking Manager | C7: 2026-07-22 | D7: IQ6 | E7: IQ6: retention targeting and prioritization - enterprise ownership noted | F7: Enterprise ownership | G7: Enterprise ownership | H7: "Retention fails when it belongs to nobody; it needs business, data, tech and CX at one table." [SYNTHETIC] | I7: Cross-functional ownership M=3.42 | J7: Converges | K7: SYNTHETIC demo coding for methods illustration.
A8: P01 | B8: Digital Banking Manager | C8: 2026-07-23 | D8: IQ7 | E8: IQ7: treatment selection and timing - trust noted | F8: Trust | G8: Trust | H8: "Once trust drops after a fraud scare, activity migrates quietly." [SYNTHETIC] | I8: Trust M=3.35 | J8: Converges | K8: SYNTHETIC demo coding for methods illustration.
A9: P01 | B9: Digital Banking Manager | C9: 2026-07-08 | D9: IQ8 | E9: IQ8: human oversight and accountability - early warning noted | F9: Early warning | G9: Early warning | H9: "The model can identify a customer who is likely to leave, but if the bank does nothing with that information, the prediction has no commercial value." [P03 seed paraphrase - SYNTHETIC] [SYNTHETIC] | I9: Risk scoring M=3.38 | J9: Converges | K9: SYNTHETIC demo coding for methods illustration.
A10: P01 | B10: Digital Banking Manager | C10: 2026-07-27 | D10: IQ9 | E10: IQ9: data integration and quality - human oversight noted | F10: Human oversight | G10: Human oversight | H10: "The data team can build the model, but they cannot be responsible for the entire retention outcome. The business has to own the outcome." [P04 seed paraphrase - SYNTHETIC] [SYNTHETIC] | I10: Human oversight M=3.18 | J10: Converges | K10: SYNTHETIC demo coding for methods illustration.
A11: P01 | B11: Digital Banking Manager | C11: 2026-07-14 | D11: IQ10 | E11: IQ10: cross-functional ownership - operational action noted | F11: Operational action | G11: Operational action | H11: "Scores sitting in a dashboard change nothing; someone must own the next action." [SYNTHETIC] | I11: AI insight integration M=2.58 | J11: Complements | K11: SYNTHETIC demo coding for methods illustration.
A12: P01 | B12: Digital Banking Manager | C12: 2026-07-14 | D12: IQ11 | E12: IQ11: governance, NDPA compliance, fairness - targeting noted | F12: Targeting | G12: Targeting | H12: "Treat everyone the same and you waste budget and annoy customers." [SYNTHETIC] | I12: Risk plus value M=3.40 | J12: Converges | K12: SYNTHETIC demo coding for methods illustration.
